{
  "cells": [
    {
      "cell_type": "code",
      "execution_count": null,
      "metadata": {
        "colab": {
          "base_uri": "https://localhost:8080/"
        },
        "id": "GAx-ax-RV2tR",
        "outputId": "624ba1b1-cd2f-416e-8d7c-0a1a50ac7da0"
      },
      "outputs": [
        {
          "name": "stdout",
          "output_type": "stream",
          "text": [
            "Collecting transliterate\n",
            "  Downloading transliterate-1.10.2-py2.py3-none-any.whl.metadata (14 kB)\n",
            "Requirement already satisfied: six>=1.1.0 in /usr/local/lib/python3.11/dist-packages (from transliterate) (1.17.0)\n",
            "Downloading transliterate-1.10.2-py2.py3-none-any.whl (45 kB)\n",
            "\u001b[?25l   \u001b[90m━━━━━━━━━━━━━━━━━━━━━━━━━━━━━━━━━━━━━━━━\u001b[0m \u001b[32m0.0/45.8 kB\u001b[0m \u001b[31m?\u001b[0m eta \u001b[36m-:--:--\u001b[0m\r\u001b[2K   \u001b[90m━━━━━━━━━━━━━━━━━━━━━━━━━━━━━━━━━━━━━━━━\u001b[0m \u001b[32m45.8/45.8 kB\u001b[0m \u001b[31m5.2 MB/s\u001b[0m eta \u001b[36m0:00:00\u001b[0m\n",
            "\u001b[?25hInstalling collected packages: transliterate\n",
            "Successfully installed transliterate-1.10.2\n"
          ]
        }
      ],
      "source": [
        "!pip install transliterate"
      ]
    },
    {
      "cell_type": "code",
      "execution_count": null,
      "metadata": {
        "colab": {
          "base_uri": "https://localhost:8080/"
        },
        "id": "3ibIXJD3R3xH",
        "outputId": "f0b2cf79-cab8-4ed6-cdea-8fda068f64d4"
      },
      "outputs": [
        {
          "name": "stderr",
          "output_type": "stream",
          "text": [
            "Asking to truncate to max_length but no maximum length is provided and the model has no predefined maximum length. Default to no truncation.\n"
          ]
        },
        {
          "name": "stdout",
          "output_type": "stream",
          "text": [
            "EN: The party shall deliver the goods within 10 days.\n",
            "SRC: Stranka će isporučiti robu u roku od 10 dana.\n",
            "SRL: Stranka će isporučiti robu u roku od 10 dana.\n",
            "\n",
            "EN: This contract is governed by the laws of the Republic of Serbia.\n",
            "SRC: Овај уговор регулишу закони Републике Србије.\n",
            "SRL: Ovaj ugovor regulišu zakoni Republike Srbije.\n",
            "\n",
            "EN: The supplier guarantees the quality of the service.\n",
            "SRC: Провајдер гарантује квалитет услуге.\n",
            "SRL: Provajder garantuje kvalitet usluge.\n",
            "\n"
          ]
        }
      ],
      "source": [
        "from transformers import M2M100ForConditionalGeneration, M2M100Tokenizer\n",
        "from transliterate import translit\n",
        "\n",
        "\n",
        "\n",
        "model_name = \"facebook/m2m100_1.2B\"\n",
        "tokenizer = M2M100Tokenizer.from_pretrained(model_name)\n",
        "model = M2M100ForConditionalGeneration.from_pretrained(model_name)\n",
        "model.to('cuda')\n",
        "\n",
        "tokenizer.src_lang = \"en\"\n",
        "target_lang = \"sr\"\n",
        "\n",
        "\n",
        "sentences = [\n",
        "    \"The party shall deliver the goods within 10 days.\",\n",
        "    \"This contract is governed by the laws of the Republic of Serbia.\",\n",
        "    \"The supplier guarantees the quality of the service.\"\n",
        "]\n",
        "\n",
        "\n",
        "inputs = tokenizer(sentences, return_tensors=\"pt\", padding=True, truncation=True).to('cuda')\n",
        "\n",
        "\n",
        "generated_tokens = model.generate(\n",
        "    **inputs,\n",
        "    forced_bos_token_id=tokenizer.get_lang_id(target_lang)\n",
        ")\n",
        "\n",
        "\n",
        "translations = tokenizer.batch_decode(generated_tokens, skip_special_tokens=True)\n",
        "\n",
        "\n",
        "for en, sr in zip(sentences, translations):\n",
        "    output_latin = translit(sr, 'sr', reversed=True)  # Cyrillic → Latin\n",
        "    print(f\"EN: {en}\\nSRC: {sr}\\nSRL: {output_latin}\\n\")\n"
      ]
    },
    {
      "cell_type": "code",
      "execution_count": null,
      "metadata": {
        "colab": {
          "base_uri": "https://localhost:8080/"
        },
        "id": "gzm6Ms4fXhXp",
        "outputId": "9ffe2b8a-8b4c-4d96-f197-3fc644504157"
      },
      "outputs": [
        {
          "name": "stdout",
          "output_type": "stream",
          "text": [
            "Requirement already satisfied: fastapi in /usr/local/lib/python3.11/dist-packages (0.116.1)\n",
            "Requirement already satisfied: uvicorn in /usr/local/lib/python3.11/dist-packages (0.35.0)\n",
            "Requirement already satisfied: transformers in /usr/local/lib/python3.11/dist-packages (4.55.0)\n",
            "Requirement already satisfied: torch in /usr/local/lib/python3.11/dist-packages (2.6.0+cu124)\n",
            "Requirement already satisfied: starlette<0.48.0,>=0.40.0 in /usr/local/lib/python3.11/dist-packages (from fastapi) (0.47.2)\n",
            "Requirement already satisfied: pydantic!=1.8,!=1.8.1,!=2.0.0,!=2.0.1,!=2.1.0,<3.0.0,>=1.7.4 in /usr/local/lib/python3.11/dist-packages (from fastapi) (2.11.7)\n",
            "Requirement already satisfied: typing-extensions>=4.8.0 in /usr/local/lib/python3.11/dist-packages (from fastapi) (4.14.1)\n",
            "Requirement already satisfied: click>=7.0 in /usr/local/lib/python3.11/dist-packages (from uvicorn) (8.2.1)\n",
            "Requirement already satisfied: h11>=0.8 in /usr/local/lib/python3.11/dist-packages (from uvicorn) (0.16.0)\n",
            "Requirement already satisfied: filelock in /usr/local/lib/python3.11/dist-packages (from transformers) (3.18.0)\n",
            "Requirement already satisfied: huggingface-hub<1.0,>=0.34.0 in /usr/local/lib/python3.11/dist-packages (from transformers) (0.34.3)\n",
            "Requirement already satisfied: numpy>=1.17 in /usr/local/lib/python3.11/dist-packages (from transformers) (2.0.2)\n",
            "Requirement already satisfied: packaging>=20.0 in /usr/local/lib/python3.11/dist-packages (from transformers) (25.0)\n",
            "Requirement already satisfied: pyyaml>=5.1 in /usr/local/lib/python3.11/dist-packages (from transformers) (6.0.2)\n",
            "Requirement already satisfied: regex!=2019.12.17 in /usr/local/lib/python3.11/dist-packages (from transformers) (2024.11.6)\n",
            "Requirement already satisfied: requests in /usr/local/lib/python3.11/dist-packages (from transformers) (2.32.3)\n",
            "Requirement already satisfied: tokenizers<0.22,>=0.21 in /usr/local/lib/python3.11/dist-packages (from transformers) (0.21.4)\n",
            "Requirement already satisfied: safetensors>=0.4.3 in /usr/local/lib/python3.11/dist-packages (from transformers) (0.6.1)\n",
            "Requirement already satisfied: tqdm>=4.27 in /usr/local/lib/python3.11/dist-packages (from transformers) (4.67.1)\n",
            "Requirement already satisfied: networkx in /usr/local/lib/python3.11/dist-packages (from torch) (3.5)\n",
            "Requirement already satisfied: jinja2 in /usr/local/lib/python3.11/dist-packages (from torch) (3.1.6)\n",
            "Requirement already satisfied: fsspec in /usr/local/lib/python3.11/dist-packages (from torch) (2025.3.0)\n",
            "Requirement already satisfied: nvidia-cuda-nvrtc-cu12==12.4.127 in /usr/local/lib/python3.11/dist-packages (from torch) (12.4.127)\n",
            "Requirement already satisfied: nvidia-cuda-runtime-cu12==12.4.127 in /usr/local/lib/python3.11/dist-packages (from torch) (12.4.127)\n",
            "Requirement already satisfied: nvidia-cuda-cupti-cu12==12.4.127 in /usr/local/lib/python3.11/dist-packages (from torch) (12.4.127)\n",
            "Requirement already satisfied: nvidia-cudnn-cu12==9.1.0.70 in /usr/local/lib/python3.11/dist-packages (from torch) (9.1.0.70)\n",
            "Requirement already satisfied: nvidia-cublas-cu12==12.4.5.8 in /usr/local/lib/python3.11/dist-packages (from torch) (12.4.5.8)\n",
            "Requirement already satisfied: nvidia-cufft-cu12==11.2.1.3 in /usr/local/lib/python3.11/dist-packages (from torch) (11.2.1.3)\n",
            "Requirement already satisfied: nvidia-curand-cu12==10.3.5.147 in /usr/local/lib/python3.11/dist-packages (from torch) (10.3.5.147)\n",
            "Requirement already satisfied: nvidia-cusolver-cu12==11.6.1.9 in /usr/local/lib/python3.11/dist-packages (from torch) (11.6.1.9)\n",
            "Requirement already satisfied: nvidia-cusparse-cu12==12.3.1.170 in /usr/local/lib/python3.11/dist-packages (from torch) (12.3.1.170)\n",
            "Requirement already satisfied: nvidia-cusparselt-cu12==0.6.2 in /usr/local/lib/python3.11/dist-packages (from torch) (0.6.2)\n",
            "Requirement already satisfied: nvidia-nccl-cu12==2.21.5 in /usr/local/lib/python3.11/dist-packages (from torch) (2.21.5)\n",
            "Requirement already satisfied: nvidia-nvtx-cu12==12.4.127 in /usr/local/lib/python3.11/dist-packages (from torch) (12.4.127)\n",
            "Requirement already satisfied: nvidia-nvjitlink-cu12==12.4.127 in /usr/local/lib/python3.11/dist-packages (from torch) (12.4.127)\n",
            "Requirement already satisfied: triton==3.2.0 in /usr/local/lib/python3.11/dist-packages (from torch) (3.2.0)\n",
            "Requirement already satisfied: sympy==1.13.1 in /usr/local/lib/python3.11/dist-packages (from torch) (1.13.1)\n",
            "Requirement already satisfied: mpmath<1.4,>=1.1.0 in /usr/local/lib/python3.11/dist-packages (from sympy==1.13.1->torch) (1.3.0)\n",
            "Requirement already satisfied: hf-xet<2.0.0,>=1.1.3 in /usr/local/lib/python3.11/dist-packages (from huggingface-hub<1.0,>=0.34.0->transformers) (1.1.7)\n",
            "Requirement already satisfied: annotated-types>=0.6.0 in /usr/local/lib/python3.11/dist-packages (from pydantic!=1.8,!=1.8.1,!=2.0.0,!=2.0.1,!=2.1.0,<3.0.0,>=1.7.4->fastapi) (0.7.0)\n",
            "Requirement already satisfied: pydantic-core==2.33.2 in /usr/local/lib/python3.11/dist-packages (from pydantic!=1.8,!=1.8.1,!=2.0.0,!=2.0.1,!=2.1.0,<3.0.0,>=1.7.4->fastapi) (2.33.2)\n",
            "Requirement already satisfied: typing-inspection>=0.4.0 in /usr/local/lib/python3.11/dist-packages (from pydantic!=1.8,!=1.8.1,!=2.0.0,!=2.0.1,!=2.1.0,<3.0.0,>=1.7.4->fastapi) (0.4.1)\n",
            "Requirement already satisfied: anyio<5,>=3.6.2 in /usr/local/lib/python3.11/dist-packages (from starlette<0.48.0,>=0.40.0->fastapi) (4.10.0)\n",
            "Requirement already satisfied: MarkupSafe>=2.0 in /usr/local/lib/python3.11/dist-packages (from jinja2->torch) (3.0.2)\n",
            "Requirement already satisfied: charset-normalizer<4,>=2 in /usr/local/lib/python3.11/dist-packages (from requests->transformers) (3.4.2)\n",
            "Requirement already satisfied: idna<4,>=2.5 in /usr/local/lib/python3.11/dist-packages (from requests->transformers) (3.10)\n",
            "Requirement already satisfied: urllib3<3,>=1.21.1 in /usr/local/lib/python3.11/dist-packages (from requests->transformers) (2.5.0)\n",
            "Requirement already satisfied: certifi>=2017.4.17 in /usr/local/lib/python3.11/dist-packages (from requests->transformers) (2025.8.3)\n",
            "Requirement already satisfied: sniffio>=1.1 in /usr/local/lib/python3.11/dist-packages (from anyio<5,>=3.6.2->starlette<0.48.0,>=0.40.0->fastapi) (1.3.1)\n"
          ]
        }
      ],
      "source": [
        "!pip install fastapi uvicorn transformers torch"
      ]
    },
    {
      "cell_type": "code",
      "execution_count": null,
      "metadata": {
        "colab": {
          "background_save": true
        },
        "id": "amod9r55XXOz",
        "outputId": "eb5b7e62-a25e-4371-9169-9d71b7028ca8"
      },
      "outputs": [
        {
          "name": "stderr",
          "output_type": "stream",
          "text": [
            "ERROR:root:Internal Python error in the inspect module.\n",
            "Below is the traceback from this internal error.\n",
            "\n",
            "ERROR:root:Internal Python error in the inspect module.\n",
            "Below is the traceback from this internal error.\n",
            "\n",
            "ERROR:root:Internal Python error in the inspect module.\n",
            "Below is the traceback from this internal error.\n",
            "\n"
          ]
        },
        {
          "name": "stdout",
          "output_type": "stream",
          "text": [
            "Traceback (most recent call last):\n",
            "  File \"/usr/local/lib/python3.11/dist-packages/IPython/core/interactiveshell.py\", line 3553, in run_code\n",
            "    exec(code_obj, self.user_global_ns, self.user_ns)\n",
            "  File \"/tmp/ipython-input-1289592227.py\", line 3, in <cell line: 0>\n",
            "    from transformers import M2M100ForConditionalGeneration, M2M100Tokenizer\n",
            "  File \"/usr/local/lib/python3.11/dist-packages/transformers/__init__.py\", line 27, in <module>\n",
            "    from . import dependency_versions_check\n",
            "  File \"/usr/local/lib/python3.11/dist-packages/transformers/dependency_versions_check.py\", line 16, in <module>\n",
            "    from .utils.versions import require_version, require_version_core\n",
            "  File \"/usr/local/lib/python3.11/dist-packages/transformers/utils/__init__.py\", line 24, in <module>\n",
            "    from .auto_docstring import (\n",
            "  File \"/usr/local/lib/python3.11/dist-packages/transformers/utils/auto_docstring.py\", line 30, in <module>\n",
            "    from .generic import ModelOutput\n",
            "  File \"/usr/local/lib/python3.11/dist-packages/transformers/utils/generic.py\", line 53, in <module>\n",
            "    import torch  # noqa: F401\n",
            "    ^^^^^^^^^^^^\n",
            "  File \"/usr/local/lib/python3.11/dist-packages/torch/__init__.py\", line 2151, in <module>\n",
            "    from torch import (\n",
            "  File \"/usr/local/lib/python3.11/dist-packages/torch/profiler/__init__.py\", line 42, in <module>\n",
            "    from . import itt\n",
            "  File \"<frozen importlib._bootstrap>\", line 1176, in _find_and_load\n",
            "  File \"<frozen importlib._bootstrap>\", line 1138, in _find_and_load_unlocked\n",
            "  File \"<frozen importlib._bootstrap>\", line 1078, in _find_spec\n",
            "  File \"<frozen importlib._bootstrap_external>\", line 1507, in find_spec\n",
            "  File \"<frozen importlib._bootstrap_external>\", line 1479, in _get_spec\n",
            "  File \"<frozen importlib._bootstrap_external>\", line None, in find_spec\n",
            "KeyboardInterrupt\n",
            "\n",
            "During handling of the above exception, another exception occurred:\n",
            "\n",
            "Traceback (most recent call last):\n",
            "  File \"/usr/local/lib/python3.11/dist-packages/IPython/core/interactiveshell.py\", line 2099, in showtraceback\n",
            "    stb = value._render_traceback_()\n",
            "          ^^^^^^^^^^^^^^^^^^^^^^^^\n",
            "AttributeError: 'KeyboardInterrupt' object has no attribute '_render_traceback_'\n",
            "\n",
            "During handling of the above exception, another exception occurred:\n",
            "\n",
            "Traceback (most recent call last):\n",
            "  File \"/usr/local/lib/python3.11/dist-packages/IPython/core/ultratb.py\", line 1101, in get_records\n",
            "    return _fixed_getinnerframes(etb, number_of_lines_of_context, tb_offset)\n",
            "           ^^^^^^^^^^^^^^^^^^^^^^^^^^^^^^^^^^^^^^^^^^^^^^^^^^^^^^^^^^^^^^^^^\n",
            "  File \"/usr/local/lib/python3.11/dist-packages/IPython/core/ultratb.py\", line 248, in wrapped\n",
            "    return f(*args, **kwargs)\n",
            "           ^^^^^^^^^^^^^^^^^^\n",
            "  File \"/usr/local/lib/python3.11/dist-packages/IPython/core/ultratb.py\", line 281, in _fixed_getinnerframes\n",
            "    records = fix_frame_records_filenames(inspect.getinnerframes(etb, context))\n",
            "                                          ^^^^^^^^^^^^^^^^^^^^^^^^^^^^^^^^^^^^\n",
            "  File \"/usr/lib/python3.11/inspect.py\", line 1739, in getinnerframes\n",
            "    traceback_info = getframeinfo(tb, context)\n",
            "                     ^^^^^^^^^^^^^^^^^^^^^^^^^\n",
            "  File \"/usr/lib/python3.11/inspect.py\", line 1686, in getframeinfo\n",
            "    start = lineno - 1 - context//2\n",
            "            ~~~~~~~^~~\n",
            "TypeError: unsupported operand type(s) for -: 'NoneType' and 'int'\n",
            "Traceback (most recent call last):\n",
            "  File \"/usr/local/lib/python3.11/dist-packages/IPython/core/interactiveshell.py\", line 3553, in run_code\n",
            "    exec(code_obj, self.user_global_ns, self.user_ns)\n",
            "  File \"/tmp/ipython-input-1289592227.py\", line 3, in <cell line: 0>\n",
            "    from transformers import M2M100ForConditionalGeneration, M2M100Tokenizer\n",
            "  File \"/usr/local/lib/python3.11/dist-packages/transformers/__init__.py\", line 27, in <module>\n",
            "    from . import dependency_versions_check\n",
            "  File \"/usr/local/lib/python3.11/dist-packages/transformers/dependency_versions_check.py\", line 16, in <module>\n",
            "    from .utils.versions import require_version, require_version_core\n",
            "  File \"/usr/local/lib/python3.11/dist-packages/transformers/utils/__init__.py\", line 24, in <module>\n",
            "    from .auto_docstring import (\n",
            "  File \"/usr/local/lib/python3.11/dist-packages/transformers/utils/auto_docstring.py\", line 30, in <module>\n",
            "    from .generic import ModelOutput\n",
            "  File \"/usr/local/lib/python3.11/dist-packages/transformers/utils/generic.py\", line 53, in <module>\n",
            "    import torch  # noqa: F401\n",
            "    ^^^^^^^^^^^^\n",
            "  File \"/usr/local/lib/python3.11/dist-packages/torch/__init__.py\", line 2151, in <module>\n",
            "    from torch import (\n",
            "  File \"/usr/local/lib/python3.11/dist-packages/torch/profiler/__init__.py\", line 42, in <module>\n",
            "    from . import itt\n",
            "  File \"<frozen importlib._bootstrap>\", line 1176, in _find_and_load\n",
            "  File \"<frozen importlib._bootstrap>\", line 1138, in _find_and_load_unlocked\n",
            "  File \"<frozen importlib._bootstrap>\", line 1078, in _find_spec\n",
            "  File \"<frozen importlib._bootstrap_external>\", line 1507, in find_spec\n",
            "  File \"<frozen importlib._bootstrap_external>\", line 1479, in _get_spec\n",
            "  File \"<frozen importlib._bootstrap_external>\", line None, in find_spec\n",
            "KeyboardInterrupt\n",
            "\n",
            "During handling of the above exception, another exception occurred:\n",
            "\n",
            "Traceback (most recent call last):\n",
            "  File \"/usr/local/lib/python3.11/dist-packages/IPython/core/interactiveshell.py\", line 2099, in showtraceback\n",
            "    stb = value._render_traceback_()\n",
            "          ^^^^^^^^^^^^^^^^^^^^^^^^\n",
            "AttributeError: 'KeyboardInterrupt' object has no attribute '_render_traceback_'\n",
            "\n",
            "During handling of the above exception, another exception occurred:\n",
            "\n",
            "Traceback (most recent call last):\n",
            "  File \"/usr/local/lib/python3.11/dist-packages/IPython/core/interactiveshell.py\", line 3473, in run_ast_nodes\n",
            "    if (await self.run_code(code, result,  async_=asy)):\n",
            "        ^^^^^^^^^^^^^^^^^^^^^^^^^^^^^^^^^^^^^^^^^^^^^^\n",
            "  File \"/usr/local/lib/python3.11/dist-packages/IPython/core/interactiveshell.py\", line 3575, in run_code\n",
            "    self.showtraceback(running_compiled_code=True)\n",
            "  File \"/usr/local/lib/python3.11/dist-packages/IPython/core/interactiveshell.py\", line 2101, in showtraceback\n",
            "    stb = self.InteractiveTB.structured_traceback(etype,\n",
            "          ^^^^^^^^^^^^^^^^^^^^^^^^^^^^^^^^^^^^^^^^^^^^^^\n",
            "  File \"/usr/local/lib/python3.11/dist-packages/IPython/core/ultratb.py\", line 1367, in structured_traceback\n",
            "    return FormattedTB.structured_traceback(\n",
            "           ^^^^^^^^^^^^^^^^^^^^^^^^^^^^^^^^^\n",
            "  File \"/usr/local/lib/python3.11/dist-packages/IPython/core/ultratb.py\", line 1267, in structured_traceback\n",
            "    return VerboseTB.structured_traceback(\n",
            "           ^^^^^^^^^^^^^^^^^^^^^^^^^^^^^^^\n",
            "  File \"/usr/local/lib/python3.11/dist-packages/IPython/core/ultratb.py\", line 1124, in structured_traceback\n",
            "    formatted_exception = self.format_exception_as_a_whole(etype, evalue, etb, number_of_lines_of_context,\n",
            "                          ^^^^^^^^^^^^^^^^^^^^^^^^^^^^^^^^^^^^^^^^^^^^^^^^^^^^^^^^^^^^^^^^^^^^^^^^^^^^^^^^\n",
            "  File \"/usr/local/lib/python3.11/dist-packages/IPython/core/ultratb.py\", line 1082, in format_exception_as_a_whole\n",
            "    last_unique, recursion_repeat = find_recursion(orig_etype, evalue, records)\n",
            "                                    ^^^^^^^^^^^^^^^^^^^^^^^^^^^^^^^^^^^^^^^^^^^\n",
            "  File \"/usr/local/lib/python3.11/dist-packages/IPython/core/ultratb.py\", line 382, in find_recursion\n",
            "    return len(records), 0\n",
            "           ^^^^^^^^^^^^\n",
            "TypeError: object of type 'NoneType' has no len()\n",
            "\n",
            "During handling of the above exception, another exception occurred:\n",
            "\n",
            "Traceback (most recent call last):\n",
            "  File \"/usr/local/lib/python3.11/dist-packages/IPython/core/interactiveshell.py\", line 2099, in showtraceback\n",
            "    stb = value._render_traceback_()\n",
            "          ^^^^^^^^^^^^^^^^^^^^^^^^\n",
            "AttributeError: 'TypeError' object has no attribute '_render_traceback_'\n",
            "\n",
            "During handling of the above exception, another exception occurred:\n",
            "\n",
            "Traceback (most recent call last):\n",
            "  File \"/usr/local/lib/python3.11/dist-packages/IPython/core/ultratb.py\", line 1101, in get_records\n",
            "    return _fixed_getinnerframes(etb, number_of_lines_of_context, tb_offset)\n",
            "           ^^^^^^^^^^^^^^^^^^^^^^^^^^^^^^^^^^^^^^^^^^^^^^^^^^^^^^^^^^^^^^^^^\n",
            "  File \"/usr/local/lib/python3.11/dist-packages/IPython/core/ultratb.py\", line 248, in wrapped\n",
            "    return f(*args, **kwargs)\n",
            "           ^^^^^^^^^^^^^^^^^^\n",
            "  File \"/usr/local/lib/python3.11/dist-packages/IPython/core/ultratb.py\", line 281, in _fixed_getinnerframes\n",
            "    records = fix_frame_records_filenames(inspect.getinnerframes(etb, context))\n",
            "                                          ^^^^^^^^^^^^^^^^^^^^^^^^^^^^^^^^^^^^\n",
            "  File \"/usr/lib/python3.11/inspect.py\", line 1739, in getinnerframes\n",
            "    traceback_info = getframeinfo(tb, context)\n",
            "                     ^^^^^^^^^^^^^^^^^^^^^^^^^\n",
            "  File \"/usr/lib/python3.11/inspect.py\", line 1686, in getframeinfo\n",
            "    start = lineno - 1 - context//2\n",
            "            ~~~~~~~^~~\n",
            "TypeError: unsupported operand type(s) for -: 'NoneType' and 'int'\n",
            "Traceback (most recent call last):\n",
            "  File \"/usr/local/lib/python3.11/dist-packages/IPython/core/interactiveshell.py\", line 3553, in run_code\n",
            "    exec(code_obj, self.user_global_ns, self.user_ns)\n",
            "  File \"/tmp/ipython-input-1289592227.py\", line 3, in <cell line: 0>\n",
            "    from transformers import M2M100ForConditionalGeneration, M2M100Tokenizer\n",
            "  File \"/usr/local/lib/python3.11/dist-packages/transformers/__init__.py\", line 27, in <module>\n",
            "    from . import dependency_versions_check\n",
            "  File \"/usr/local/lib/python3.11/dist-packages/transformers/dependency_versions_check.py\", line 16, in <module>\n",
            "    from .utils.versions import require_version, require_version_core\n",
            "  File \"/usr/local/lib/python3.11/dist-packages/transformers/utils/__init__.py\", line 24, in <module>\n",
            "    from .auto_docstring import (\n",
            "  File \"/usr/local/lib/python3.11/dist-packages/transformers/utils/auto_docstring.py\", line 30, in <module>\n",
            "    from .generic import ModelOutput\n",
            "  File \"/usr/local/lib/python3.11/dist-packages/transformers/utils/generic.py\", line 53, in <module>\n",
            "    import torch  # noqa: F401\n",
            "    ^^^^^^^^^^^^\n",
            "  File \"/usr/local/lib/python3.11/dist-packages/torch/__init__.py\", line 2151, in <module>\n",
            "    from torch import (\n",
            "  File \"/usr/local/lib/python3.11/dist-packages/torch/profiler/__init__.py\", line 42, in <module>\n",
            "    from . import itt\n",
            "  File \"<frozen importlib._bootstrap>\", line 1176, in _find_and_load\n",
            "  File \"<frozen importlib._bootstrap>\", line 1138, in _find_and_load_unlocked\n",
            "  File \"<frozen importlib._bootstrap>\", line 1078, in _find_spec\n",
            "  File \"<frozen importlib._bootstrap_external>\", line 1507, in find_spec\n",
            "  File \"<frozen importlib._bootstrap_external>\", line 1479, in _get_spec\n",
            "  File \"<frozen importlib._bootstrap_external>\", line None, in find_spec\n",
            "KeyboardInterrupt\n",
            "\n",
            "During handling of the above exception, another exception occurred:\n",
            "\n",
            "Traceback (most recent call last):\n",
            "  File \"/usr/local/lib/python3.11/dist-packages/IPython/core/interactiveshell.py\", line 2099, in showtraceback\n",
            "    stb = value._render_traceback_()\n",
            "          ^^^^^^^^^^^^^^^^^^^^^^^^\n",
            "AttributeError: 'KeyboardInterrupt' object has no attribute '_render_traceback_'\n",
            "\n",
            "During handling of the above exception, another exception occurred:\n",
            "\n",
            "Traceback (most recent call last):\n",
            "  File \"/usr/local/lib/python3.11/dist-packages/IPython/core/interactiveshell.py\", line 3473, in run_ast_nodes\n",
            "    if (await self.run_code(code, result,  async_=asy)):\n",
            "        ^^^^^^^^^^^^^^^^^^^^^^^^^^^^^^^^^^^^^^^^^^^^^^\n",
            "  File \"/usr/local/lib/python3.11/dist-packages/IPython/core/interactiveshell.py\", line 3575, in run_code\n",
            "    self.showtraceback(running_compiled_code=True)\n",
            "  File \"/usr/local/lib/python3.11/dist-packages/IPython/core/interactiveshell.py\", line 2101, in showtraceback\n",
            "    stb = self.InteractiveTB.structured_traceback(etype,\n",
            "          ^^^^^^^^^^^^^^^^^^^^^^^^^^^^^^^^^^^^^^^^^^^^^^\n",
            "  File \"/usr/local/lib/python3.11/dist-packages/IPython/core/ultratb.py\", line 1367, in structured_traceback\n",
            "    return FormattedTB.structured_traceback(\n",
            "           ^^^^^^^^^^^^^^^^^^^^^^^^^^^^^^^^^\n",
            "  File \"/usr/local/lib/python3.11/dist-packages/IPython/core/ultratb.py\", line 1267, in structured_traceback\n",
            "    return VerboseTB.structured_traceback(\n",
            "           ^^^^^^^^^^^^^^^^^^^^^^^^^^^^^^^\n",
            "  File \"/usr/local/lib/python3.11/dist-packages/IPython/core/ultratb.py\", line 1124, in structured_traceback\n",
            "    formatted_exception = self.format_exception_as_a_whole(etype, evalue, etb, number_of_lines_of_context,\n",
            "                          ^^^^^^^^^^^^^^^^^^^^^^^^^^^^^^^^^^^^^^^^^^^^^^^^^^^^^^^^^^^^^^^^^^^^^^^^^^^^^^^^\n",
            "  File \"/usr/local/lib/python3.11/dist-packages/IPython/core/ultratb.py\", line 1082, in format_exception_as_a_whole\n",
            "    last_unique, recursion_repeat = find_recursion(orig_etype, evalue, records)\n",
            "                                    ^^^^^^^^^^^^^^^^^^^^^^^^^^^^^^^^^^^^^^^^^^^\n",
            "  File \"/usr/local/lib/python3.11/dist-packages/IPython/core/ultratb.py\", line 382, in find_recursion\n",
            "    return len(records), 0\n",
            "           ^^^^^^^^^^^^\n",
            "TypeError: object of type 'NoneType' has no len()\n",
            "\n",
            "During handling of the above exception, another exception occurred:\n",
            "\n",
            "Traceback (most recent call last):\n",
            "  File \"/usr/local/lib/python3.11/dist-packages/IPython/core/interactiveshell.py\", line 2099, in showtraceback\n",
            "    stb = value._render_traceback_()\n",
            "          ^^^^^^^^^^^^^^^^^^^^^^^^\n",
            "AttributeError: 'TypeError' object has no attribute '_render_traceback_'\n",
            "\n",
            "During handling of the above exception, another exception occurred:\n",
            "\n",
            "Traceback (most recent call last):\n",
            "  File \"/usr/local/lib/python3.11/dist-packages/IPython/core/interactiveshell.py\", line 3030, in _run_cell\n",
            "    return runner(coro)\n",
            "           ^^^^^^^^^^^^\n",
            "  File \"/usr/local/lib/python3.11/dist-packages/IPython/core/async_helpers.py\", line 78, in _pseudo_sync_runner\n",
            "    coro.send(None)\n",
            "  File \"/usr/local/lib/python3.11/dist-packages/IPython/core/interactiveshell.py\", line 3257, in run_cell_async\n",
            "    has_raised = await self.run_ast_nodes(code_ast.body, cell_name,\n",
            "                 ^^^^^^^^^^^^^^^^^^^^^^^^^^^^^^^^^^^^^^^^^^^^^^^^^^\n",
            "  File \"/usr/local/lib/python3.11/dist-packages/IPython/core/interactiveshell.py\", line 3492, in run_ast_nodes\n",
            "    self.showtraceback()\n",
            "  File \"/usr/local/lib/python3.11/dist-packages/IPython/core/interactiveshell.py\", line 2101, in showtraceback\n",
            "    stb = self.InteractiveTB.structured_traceback(etype,\n",
            "          ^^^^^^^^^^^^^^^^^^^^^^^^^^^^^^^^^^^^^^^^^^^^^^\n",
            "  File \"/usr/local/lib/python3.11/dist-packages/IPython/core/ultratb.py\", line 1367, in structured_traceback\n",
            "    return FormattedTB.structured_traceback(\n",
            "           ^^^^^^^^^^^^^^^^^^^^^^^^^^^^^^^^^\n",
            "  File \"/usr/local/lib/python3.11/dist-packages/IPython/core/ultratb.py\", line 1267, in structured_traceback\n",
            "    return VerboseTB.structured_traceback(\n",
            "           ^^^^^^^^^^^^^^^^^^^^^^^^^^^^^^^\n",
            "  File \"/usr/local/lib/python3.11/dist-packages/IPython/core/ultratb.py\", line 1142, in structured_traceback\n",
            "    formatted_exceptions += self.format_exception_as_a_whole(etype, evalue, etb, lines_of_context,\n",
            "                            ^^^^^^^^^^^^^^^^^^^^^^^^^^^^^^^^^^^^^^^^^^^^^^^^^^^^^^^^^^^^^^^^^^^^^^\n",
            "  File \"/usr/local/lib/python3.11/dist-packages/IPython/core/ultratb.py\", line 1082, in format_exception_as_a_whole\n",
            "    last_unique, recursion_repeat = find_recursion(orig_etype, evalue, records)\n",
            "                                    ^^^^^^^^^^^^^^^^^^^^^^^^^^^^^^^^^^^^^^^^^^^\n",
            "  File \"/usr/local/lib/python3.11/dist-packages/IPython/core/ultratb.py\", line 382, in find_recursion\n",
            "    return len(records), 0\n",
            "           ^^^^^^^^^^^^\n",
            "TypeError: object of type 'NoneType' has no len()\n",
            "\n",
            "During handling of the above exception, another exception occurred:\n",
            "\n",
            "Traceback (most recent call last):\n",
            "  File \"/usr/local/lib/python3.11/dist-packages/IPython/core/interactiveshell.py\", line 2099, in showtraceback\n",
            "    stb = value._render_traceback_()\n",
            "          ^^^^^^^^^^^^^^^^^^^^^^^^\n",
            "AttributeError: 'TypeError' object has no attribute '_render_traceback_'\n",
            "\n",
            "During handling of the above exception, another exception occurred:\n",
            "\n",
            "Traceback (most recent call last):\n",
            "  File \"/usr/local/lib/python3.11/dist-packages/IPython/core/ultratb.py\", line 1101, in get_records\n",
            "    return _fixed_getinnerframes(etb, number_of_lines_of_context, tb_offset)\n",
            "           ^^^^^^^^^^^^^^^^^^^^^^^^^^^^^^^^^^^^^^^^^^^^^^^^^^^^^^^^^^^^^^^^^\n",
            "  File \"/usr/local/lib/python3.11/dist-packages/IPython/core/ultratb.py\", line 248, in wrapped\n",
            "    return f(*args, **kwargs)\n",
            "           ^^^^^^^^^^^^^^^^^^\n",
            "  File \"/usr/local/lib/python3.11/dist-packages/IPython/core/ultratb.py\", line 281, in _fixed_getinnerframes\n",
            "    records = fix_frame_records_filenames(inspect.getinnerframes(etb, context))\n",
            "                                          ^^^^^^^^^^^^^^^^^^^^^^^^^^^^^^^^^^^^\n",
            "  File \"/usr/lib/python3.11/inspect.py\", line 1739, in getinnerframes\n",
            "    traceback_info = getframeinfo(tb, context)\n",
            "                     ^^^^^^^^^^^^^^^^^^^^^^^^^\n",
            "  File \"/usr/lib/python3.11/inspect.py\", line 1686, in getframeinfo\n",
            "    start = lineno - 1 - context//2\n",
            "            ~~~~~~~^~~\n",
            "TypeError: unsupported operand type(s) for -: 'NoneType' and 'int'\n"
          ]
        }
      ],
      "source": [
        "from fastapi import FastAPI\n",
        "from pydantic import BaseModel\n",
        "from transformers import M2M100ForConditionalGeneration, M2M100Tokenizer\n",
        "\n",
        "\n",
        "MODEL_NAME = \"facebook/m2m100_1.2B\"\n",
        "tokenizer = M2M100Tokenizer.from_pretrained(MODEL_NAME)\n",
        "model = M2M100ForConditionalGeneration.from_pretrained(MODEL_NAME)\n",
        "\n",
        "app = FastAPI(title=\"English-Serbian Translation API\")\n",
        "\n",
        "\n",
        "class TranslationRequest(BaseModel):\n",
        "    text: str\n",
        "    source_lang: str  # \"en\" or \"sr\"\n",
        "    target_lang: str  # \"en\" or \"sr\"\n",
        "\n",
        "@app.post(\"/translate\")\n",
        "def translate(req: TranslationRequest):\n",
        "    tokenizer.src_lang = req.source_lang\n",
        "    encoded = tokenizer(req.text, return_tensors=\"pt\")\n",
        "    generated = model.generate(\n",
        "        **encoded,\n",
        "        forced_bos_token_id=tokenizer.get_lang_id(req.target_lang)\n",
        "    )\n",
        "    translation = tokenizer.decode(generated[0], skip_special_tokens=True)\n",
        "    return {\"translation\": translation}\n"
      ]
    },
    {
      "cell_type": "code",
      "execution_count": null,
      "metadata": {
        "id": "s9WgajATXb14"
      },
      "outputs": [],
      "source": []
    }
  ],
  "metadata": {
    "accelerator": "GPU",
    "colab": {
      "gpuType": "T4",
      "provenance": []
    },
    "kernelspec": {
      "display_name": "Python 3",
      "name": "python3"
    },
    "language_info": {
      "name": "python"
    }
  },
  "nbformat": 4,
  "nbformat_minor": 0
}